Workbook

Sheet Change Overview
A1: SMTinel | YOKOTEN | DEVIATION + ECO CONTROL
A4: Fuente de importacion | B4: Deviation.csv + EngineeringChangeOrder.csv
A5: Fecha de evaluacion | B5: 46311
A7: INDICADORES DEL MAESTRO
A9: Desviaciones en registro | B9: =COUNTIF('Change Register'!B2:B5000,"DEVIATION") -> 487
A10: Registros CSV originales | B10: =COUNTA('Deviation Raw'!A2:A5000) -> 1890
A11: Combinaciones unicas CTAN + BU + PN | B11: =COUNTA('Deviation Items'!A2:A4000) -> 1786
A12: Reglas PCBA candidatas (DEV + ECO) | B12: =COUNTA('Change Applicability'!A2:A5000) -> 903
A13: Desviaciones con fecha fin abierta | B13: =COUNTIF('Deviation Radar'!L2:L3000,"END DATE NOT PASSED") -> 102
A14: Desviaciones con conflictos en status/alcance | B14: =COUNTIF('Deviation Radar'!K2:K3000,"?*") -> 10
A15: Alertas certificadas listas para SMTinel | B15: =COUNTIFS('Change Applicability'!Z2:Z5000,"Verified",'Change Applicability'!AA2:AA5000,"Y") -> 0
A16: Part Numbers excluidos de FJZ | B16: =COUNTIF('Deviation Items'!O2:O4000,"EXCLUDED - FJZ RULE") -> 2
A19: CRITERIOS DE PUBLICACION Y CONTROL
A21: • Fuentes: Deviation.csv y EngineeringChangeOrder.csv. Son exportables de seguimiento, NO documentos customer firmados ni permiso de sustitución.
A22: • Fecha fin abierta NO equivale a desviacion aprobada ni activa. El estado CCB, FAI Status o Implementation se muestra como fuente sin convertirlo a Approved.
A23: • Register: 487 DEV + 728 ECO de fuente. Applicability: PN 73- exacto; ECO usa REV NUEVA literal y guarda REV VIEJA como antecedente. Todas Pending Review / Active=N.
A24: • Deviation Items relaciona todos los numeros de parte (incluyendo CPN, chassis, PCB y ensambles) sin asumir que son un PCBA o material anterior/nuevo.
A25: • Deviation Raw preserva las 1,890 filas originales y evidencia de origen. Deviation Radar resume estados y candidatos para curacion.
A26: • Desviaciones sin revisión explícita quedan candidatas por PN (rev por validar), no coincidencias por revisión. No heredar automáticamente A0/B0/C0.
A27: • No aplicar automaticamente PN 73-19152-02 o 17-15768-01 en FJZ. Buscar caso explicito en documento y Common DB antes de reconsiderar.
A28: • Para alertas operativas: verificar aprobacion oficial, revision, BOM/AVL, WO, fecha de corrida, sitio y orden de cambio. Luego marcar Verified + Active=Y.
A29: • ECO ya incorporados; el Agile ECN asociado NO crea automáticamente un documento ECN separado. Los documentos ECO sin PN 73-, BU o REV confiables requieren revisión de alcance.
A32: ORDEN RECOMENDADO: SKU → REVISION → PCBA PN → DOCUMENTO → COMPONENTE → VIGENCIA → EVIDENCIA.
A34: Detalle: ECO Radar / ECO Items / ECO BOM Ops conservan las revisiones old→new, material, fuente y origen; Deviation Instructions conserva instrucciones de desviaciones.
A36: ECO | RESULTADO DE IMPORTACIÓN
A37: Documentos ECO fuente | B37: =COUNTIF('Change Register'!B2:B5000,"ECO") -> 728
A38: Filas CSV ECO originales | B38: 11011
A39: Filas con ECO # ausente / inválido | B39: 464
A40: Items ECO consolidados | B40: 5522
A41: Operaciones BOM originales deduplicadas | B41: 5765
A42: Reglas ECO PN+Rev exacta | B42: 356
A43: Revisiones simbólicas / no exactas omitidas | B43: 87
A44: ECNs independientes | B44: 0

Sheet Deviation Radar
A1: CTAN Number | B1: Cisco Deviation | C1: BU | D1: Workflow Status (source) | E1: Date Released (source) | F1: Effective To (source) | G1: CSV Rows | H1: Unique Items | I1: PCBA PN Candidates | J1: Known SKU Matches | K1: Source Conflicts | L1: Date Window (screening) | M1: Release Status (screening) | N1: Review Priority | O1: Next Action
A2: CTANJZ04014 | B2: D598638 | C2: SRGBU | D2: Closed | E2: 45514 | F2: 47790 | G2: 1 | H2: 1 | L2: =IF(F2="","REVIEW: DATE CONFLICT/EMPTY",IF(F2<'Change Overview'!$B$5,"END DATE PASSED","END DATE NOT PASSED")) -> END DATE NOT PASSED | M2: =IF(K2<>"","REVIEW SOURCE CONFLICT",IF(OR(ISNUMBER(SEARCH("CCB",D2)),ISNUMBER(SEARCH("Pending",D2))),"CCB/PENDING",IF(OR(ISNUMBER(SEARCH("Expired",D2)),ISNUMBER(SEARCH("Closed",D2))),"CLOSED/EXPIRED",IF(E2="","NO RELEASE DATE","REVIEW APPROVAL")))) -> CLOSED/EXPIRED | N2: =IF(K2<>"","HIGH: SOURCE CONFLICT",IF(AND(L2="END DATE NOT PASSED",M2="REVIEW APPROVAL"),"HIGH: VERIFY",IF(L2="END DATE NOT PASSED","MEDIUM: CHECK STATUS","LOW: HISTORICAL"))) -> MEDIUM: CHECK STATUS | O2: Validar documento firmado, revision/WO/sitio, material afectado y evidencia antes de activar alerta automatica.
A3: CTANJZ04427 | B3: D601187 | C3: STBU | D3: Expired | E3: 45713 | F3: 45775 | G3: 3 | H3: 3 | I3: 73-20249-05 | L3: =IF(F3="","REVIEW: DATE CONFLICT/EMPTY",IF(F3<'Change Overview'!$B$5,"END DATE PASSED","END DATE NOT PASSED")) -> END DATE PASSED | M3: =IF(K3<>"","REVIEW SOURCE CONFLICT",IF(OR(ISNUMBER(SEARCH("CCB",D3)),ISNUMBER(SEARCH("Pending",D3))),"CCB/PENDING",IF(OR(ISNUMBER(SEARCH("Expired",D3)),ISNUMBER(SEARCH("Closed",D3))),"CLOSED/EXPIRED",IF(E3="","NO RELEASE DATE","REVIEW APPROVAL")))) -> CLOSED/EXPIRED | N3: =IF(K3<>"","HIGH: SOURCE CONFLICT",IF(AND(L3="END DATE NOT PASSED",M3="REVIEW APPROVAL"),"HIGH: VERIFY",IF(L3="END DATE NOT PASSED","MEDIUM: CHECK STATUS","LOW: HISTORICAL"))) -> LOW: HISTORICAL | O3: Validar documento firmado, revision/WO/sitio, material afectado y evidencia antes de activar alerta automatica.
A4: CTANJZ04430 | B4: D601838 | C4: STBU | D4: Expired | E4: 45709 | F4: 45783 | G4: 1 | H4: 1 | L4: =IF(F4="","REVIEW: DATE CONFLICT/EMPTY",IF(F4<'Change Overview'!$B$5,"END DATE PASSED","END DATE NOT PASSED")) -> END DATE PASSED | M4: =IF(K4<>"","REVIEW SOURCE CONFLICT",IF(OR(ISNUMBER(SEARCH("CCB",D4)),ISNUMBER(SEARCH("Pending",D4))),"CCB/PENDING",IF(OR(ISNUMBER(SEARCH("Expired",D4)),ISNUMBER(SEARCH("Closed",D4))),"CLOSED/EXPIRED",IF(E4="","NO RELEASE DATE","REVIEW APPROVAL")))) -> CLOSED/EXPIRED | N4: =IF(K4<>"","HIGH: SOURCE CONFLICT",IF(AND(L4="END DATE NOT PASSED",M4="REVIEW APPROVAL"),"HIGH: VERIFY",IF(L4="END DATE NOT PASSED","MEDIUM: CHECK STATUS","LOW: HISTORICAL"))) -> LOW: HISTORICAL | O4: Validar documento firmado, revision/WO/sitio, material afectado y evidencia antes de activar alerta automatica.
A5: CTANJZ04431 | B5: D601949 | C5: STBU | D5: Expired | E5: 45713 | F5: 45783 | G5: 5 | H5: 5 | I5: 73-20247-05, 73-20249-05 | L5: =IF(F5="","REVIEW: DATE CONFLICT/EMPTY",IF(F5<'Change Overview'!$B$5,"END DATE PASSED","END DATE NOT PASSED")) -> END DATE PASSED | M5: =IF(K5<>"","REVIEW SOURCE CONFLICT",IF(OR(ISNUMBER(SEARCH("CCB",D5)),ISNUMBER(SEARCH("Pending",D5))),"CCB/PENDING",IF(OR(ISNUMBER(SEARCH("Expired",D5)),ISNUMBER(SEARCH("Closed",D5))),"CLOSED/EXPIRED",IF(E5="","NO RELEASE DATE","REVIEW APPROVAL")))) -> CLOSED/EXPIRED | N5: =IF(K5<>"","HIGH: SOURCE CONFLICT",IF(AND(L5="END DATE NOT PASSED",M5="REVIEW APPROVAL"),"HIGH: VERIFY",IF(L5="END DATE NOT PASSED","MEDIUM: CHECK STATUS","LOW: HISTORICAL"))) -> LOW: HISTORICAL | O5: Validar documento firmado, revision/WO/sitio, material afectado y evidencia antes de activar alerta automatica.
A6: CTANJZ04432 | B6: D601971 | C6: SRGBU | D6: Expired | E6: 45709 | F6: 45783 | G6: 2 | H6: 2 | L6: =IF(F6="","REVIEW: DATE CONFLICT/EMPTY",IF(F6<'Change Overview'!$B$5,"END DATE PASSED","END DATE NOT PASSED")) -> END DATE PASSED | M6: =IF(K6<>"","REVIEW SOURCE CONFLICT",IF(OR(ISNUMBER(SEARCH("CCB",D6)),ISNUMBER(SEARCH("Pending",D6))),"CCB/PENDING",IF(OR(ISNUMBER(SEARCH("Expired",D6)),ISNUMBER(SEARCH("Closed",D6))),"CLOSED/EXPIRED",IF(E6="","NO RELEASE DATE","REVIEW APPROVAL")))) -> CLOSED/EXPIRED | N6: =IF(K6<>"","HIGH: SOURCE CONFLICT",IF(AND(L6="END DATE NOT PASSED",M6="REVIEW APPROVAL"),"HIGH: VERIFY",IF(L6="END DATE NOT PASSED","MEDIUM: CHECK STATUS","LOW: HISTORICAL"))) -> LOW: HISTORICAL | O6: Validar documento firmado, revision/WO/sitio, material afectado y evidencia antes de activar alerta automatica.
A7: CTANJZ04435 | B7: D596346 | C7: STBU | D7: Expired | E7: 45709 | F7: 45783 | G7: 1 | H7: 1 | L7: =IF(F7="","REVIEW: DATE CONFLICT/EMPTY",IF(F7<'Change Overview'!$B$5,"END DATE PASSED","END DATE NOT PASSED")) -> END DATE PASSED | M7: =IF(K7<>"","REVIEW SOURCE CONFLICT",IF(OR(ISNUMBER(SEARCH("CCB",D7)),ISNUMBER(SEARCH("Pending",D7))),"CCB/PENDING",IF(OR(ISNUMBER(SEARCH("Expired",D7)),ISNUMBER(SEARCH("Closed",D7))),"CLOSED/EXPIRED",IF(E7="","NO RELEASE DATE","REVIEW APPROVAL")))) -> CLOSED/EXPIRED | N7: =IF(K7<>"","HIGH: SOURCE CONFLICT",IF(AND(L7="END DATE NOT PASSED",M7="REVIEW APPROVAL"),"HIGH: VERIFY",IF(L7="END DATE NOT PASSED","MEDIUM: CHECK STATUS","LOW: HISTORICAL"))) -> LOW: HISTORICAL | O7: Validar documento firmado, revision/WO/sitio, material afectado y evidencia antes de activar alerta automatica.
A8: CTANJZ04441 | B8: D601899 | C8: SRGBU | D8: Expired | E8: 45713 | F8: 45788 | G8: 3 | H8: 3 | L8: =IF(F8="","REVIEW: DATE CONFLICT/EMPTY",IF(F8<'Change Overview'!$B$5,"END DATE PASSED","END DATE NOT PASSED")) -> END DATE PASSED | M8: =IF(K8<>"","REVIEW SOURCE CONFLICT",IF(OR(ISNUMBER(SEARCH("CCB",D8)),ISNUMBER(SEARCH("Pending",D8))),"CCB/PENDING",IF(OR(ISNUMBER(SEARCH("Expired",D8)),ISNUMBER(SEARCH("Closed",D8))),"CLOSED/EXPIRED",IF(E8="","NO RELEASE DATE","REVIEW APPROVAL")))) -> CLOSED/EXPIRED | N8: =IF(K8<>"","HIGH: SOURCE CONFLICT",IF(AND(L8="END DATE NOT PASSED",M8="REVIEW APPROVAL"),"HIGH: VERIFY",IF(L8="END DATE NOT PASSED","MEDIUM: CHECK STATUS","LOW: HISTORICAL"))) -> LOW: HISTORICAL | O8: Validar documento firmado, revision/WO/sitio, material afectado y evidencia antes de activar alerta automatica.
A9: CTANJZ04443 | B9: D601883 | C9: STBU | D9: Expired | E9: 45709 | F9: 45788 | G9: 2 | H9: 2 | L9: =IF(F9="","REVIEW: DATE CONFLICT/EMPTY",IF(F9<'Change Overview'!$B$5,"END DATE PASSED","END DATE NOT PASSED")) -> END DATE PASSED | M9: =IF(K9<>"","REVIEW SOURCE CONFLICT",IF(OR(ISNUMBER(SEARCH("CCB",D9)),ISNUMBER(SEARCH("Pending",D9))),"CCB/PENDING",IF(OR(ISNUMBER(SEARCH("Expired",D9)),ISNUMBER(SEARCH("Closed",D9))),"CLOSED/EXPIRED",IF(E9="","NO RELEASE DATE","REVIEW APPROVAL")))) -> CLOSED/EXPIRED | N9: =IF(K9<>"","HIGH: SOURCE CONFLICT",IF(AND(L9="END DATE NOT PASSED",M9="REVIEW APPROVAL"),"HIGH: VERIFY",IF(L9="END DATE NOT PASSED","MEDIUM: CHECK STATUS","LOW: HISTORICAL"))) -> LOW: HISTORICAL | O9: Validar documento firmado, revision/WO/sitio, material afectado y evidencia antes de activar alerta automatica.
A10: CTANJZ04449 | B10: D602143 | C10: STBU | D10: Expired | E10: 45709 | F10: 45789 | G10: 9 | H10: 9 | I10: 73-17567-12, 73-17568-12, 73-17569-10, 73-17570-10 | L10: =IF(F10="","REVIEW: DATE CONFLICT/EMPTY",IF(F10<'Change Overview'!$B$5,"END DATE PASSED","END DATE NOT PASSED")) -> END DATE PASSED | M10: =IF(K10<>"","REVIEW SOURCE CONFLICT",IF(OR(ISNUMBER(SEARCH("CCB",D10)),ISNUMBER(SEARCH("Pending",D10))),"CCB/PENDING",IF(OR(ISNUMBER(SEARCH("Expired",D10)),ISNUMBER(SEARCH("Closed",D10))),"CLOSED/EXPIRED",IF(E10="","NO RELEASE DATE","REVIEW APPROVAL")))) -> CLOSED/EXPIRED | N10: =IF(K10<>"","HIGH: SOURCE CONFLICT",IF(AND(L10="END DATE NOT PASSED",M10="REVIEW APPROVAL"),"HIGH: VERIFY",IF(L10="END DATE NOT PASSED","MEDIUM: CHECK STATUS","LOW: HISTORICAL"))) -> LOW: HISTORICAL | O10: Validar documento firmado, revision/WO/sitio, material afectado y evidencia antes de activar alerta automatica.
A11: CTANJZ04450 | B11: D602145 | C11: STBU | D11: Expired | E11: 45713 | F11: 45789 | G11: 7 | H11: 7 | L11: =IF(F11="","REVIEW: DATE CONFLICT/EMPTY",IF(F11<'Change Overview'!$B$5,"END DATE PASSED","END DATE NOT PASSED")) -> END DATE PASSED | M11: =IF(K11<>"","REVIEW SOURCE CONFLICT",IF(OR(ISNUMBER(SEARCH("CCB",D11)),ISNUMBER(SEARCH("Pending",D11))),"CCB/PENDING",IF(OR(ISNUMBER(SEARCH("Expired",D11)),ISNUMBER(SEARCH("Closed",D11))),"CLOSED/EXPIRED",IF(E11="","NO RELEASE DATE","REVIEW APPROVAL")))) -> CLOSED/EXPIRED | N11: =IF(K11<>"","HIGH: SOURCE CONFLICT",IF(AND(L11="END DATE NOT PASSED",M11="REVIEW APPROVAL"),"HIGH: VERIFY",IF(L11="END DATE NOT PASSED","MEDIUM: CHECK STATUS","LOW: HISTORICAL"))) -> LOW: HISTORICAL | O11: Validar documento firmado, revision/WO/sitio, material afectado y evidencia antes de activar alerta automatica.
A12: CTANJZ04453 | B12: D601097 | C12: STBU | D12: Expired | E12: 45709 | F12: 45790 | G12: 3 | H12: 3 | I12: 73-17499-07 | L12: =IF(F12="","REVIEW: DATE CONFLICT/EMPTY",IF(F12<'Change Overview'!$B$5,"END DATE PASSED","END DATE NOT PASSED")) -> END DATE PASSED | M12: =IF(K12<>"","REVIEW SOURCE CONFLICT",IF(OR(ISNUMBER(SEARCH("CCB",D12)),ISNUMBER(SEARCH("Pending",D12))),"CCB/PENDING",IF(OR(ISNUMBER(SEARCH("Expired",D12)),ISNUMBER(SEARCH("Closed",D12))),"CLOSED/EXPIRED",IF(E12="","NO RELEASE DATE","REVIEW APPROVAL")))) -> CLOSED/EXPIRED | N12: =IF(K12<>"","HIGH: SOURCE CONFLICT",IF(AND(L12="END DATE NOT PASSED",M12="REVIEW APPROVAL"),"HIGH: VERIFY",IF(L12="END DATE NOT PASSED","MEDIUM: CHECK STATUS","LOW: HISTORICAL"))) -> LOW: HISTORICAL | O12: Validar documento firmado, revision/WO/sitio, material afectado y evidencia antes de activar alerta automatica.
A13: CTANJZ04465 | B13: D602184 | C13: SRGBU | D13: Expired | E13: 45713 | F13: 45796 | G13: 3 | H13: 3 | L13: =IF(F13="","REVIEW: DATE CONFLICT/EMPTY",IF(F13<'Change Overview'!$B$5,"END DATE PASSED","END DATE NOT PASSED")) -> END DATE PASSED | M13: =IF(K13<>"","REVIEW SOURCE CONFLICT",IF(OR(ISNUMBER(SEARCH("CCB",D13)),ISNUMBER(SEARCH("Pending",D13))),"CCB/PENDING",IF(OR(ISNUMBER(SEARCH("Expired",D13)),ISNUMBER(SEARCH("Closed",D13))),"CLOSED/EXPIRED",IF(E13="","NO RELEASE DATE","REVIEW APPROVAL")))) -> CLOSED/EXPIRED | N13: =IF(K13<>"","HIGH: SOURCE CONFLICT",IF(AND(L13="END DATE NOT PASSED",M13="REVIEW APPROVAL"),"HIGH: VERIFY",IF(L13="END DATE NOT PASSED","MEDIUM: CHECK STATUS","LOW: HISTORICAL"))) -> LOW: HISTORICAL | O13: Validar documento firmado, revision/WO/sitio, material afectado y evidencia antes de activar alerta automatica.
A14: CTANJZ04466 | B14: D602196 | C14: STBU | D14: Expired | E14: 45716 | F14: 45796 | G14: 5 | H14: 5 | I14: 73-17497-04, 73-17499-07, 73-20247-06, 73-20249-06 | J14: TUFNELL PARK | L14: =IF(F14="","REVIEW: DATE CONFLICT/EMPTY",IF(F14<'Change Overview'!$B$5,"END DATE PASSED","END DATE NOT PASSED")) -> END DATE PASSED | M14: =IF(K14<>"","REVIEW SOURCE CONFLICT",IF(OR(ISNUMBER(SEARCH("CCB",D14)),ISNUMBER(SEARCH("Pending",D14))),"CCB/PENDING",IF(OR(ISNUMBER(SEARCH("Expired",D14)),ISNUMBER(SEARCH("Closed",D14))),"CLOSED/EXPIRED",IF(E14="","NO RELEASE DATE","REVIEW APPROVAL")))) -> CLOSED/EXPIRED | N14: =IF(K14<>"","HIGH: SOURCE CONFLICT",IF(AND(L14="END DATE NOT PASSED",M14="REVIEW APPROVAL"),"HIGH: VERIFY",IF(L14="END DATE NOT PASSED","MEDIUM: CHECK STATUS","LOW: HISTORICAL"))) -> LOW: HISTORICAL | O14: Validar documento firmado, revision/WO/sitio, material afectado y evidencia antes de activar alerta automatica.
A15: CTANJZ04473 | B15: D602345 | C15: STBU | D15: Expired | E15: 45720 | F15: 45799 | G15: 5 | H15: 5 | L15: =IF(F15="","REVIEW: DATE CONFLICT/EMPTY",IF(F15<'Change Overview'!$B$5,"END DATE PASSED","END DATE NOT PASSED")) -> END DATE PASSED | M15: =IF(K15<>"","REVIEW SOURCE CONFLICT",IF(OR(ISNUMBER(SEARCH("CCB",D15)),ISNUMBER(SEARCH("Pending",D15))),"CCB/PENDING",IF(OR(ISNUMBER(SEARCH("Expired",D15)),ISNUMBER(SEARCH("Closed",D15))),"CLOSED/EXPIRED",IF(E15="","NO RELEASE DATE","REVIEW APPROVAL")))) -> CLOSED/EXPIRED | N15: =IF(K15<>"","HIGH: SOURCE CONFLICT",IF(AND(L15="END DATE NOT PASSED",M15="REVIEW APPROVAL"),"HIGH: VERIFY",IF(L15="END DATE NOT PASSED","MEDIUM: CHECK STATUS","LOW: HISTORICAL"))) -> LOW: HISTORICAL | O15: Validar documento firmado, revision/WO/sitio, material afectado y evidencia antes de activar alerta automatica.
A16: CTANJZ04475 | B16: D602181 | C16: SRGBU | D16: Expired | E16: 45720 | F16: 45799 | G16: 17 | H16: 17 | I16: 73-14503-08, 73-14504-09, 73-14505-09, 73-14506-08, 73-15195-05, 73-15196-05, 73-15197-05, 73-16084-04, 73-16524-03, 73-19107-04 | L16: =IF(F16="","REVIEW: DATE CONFLICT/EMPTY",IF(F16<'Change Overview'!$B$5,"END DATE PASSED","END DATE NOT PASSED")) -> END DATE PASSED | M16: =IF(K16<>"","REVIEW SOURCE CONFLICT",IF(OR(ISNUMBER(SEARCH("CCB",D16)),ISNUMBER(SEARCH("Pending",D16))),"CCB/PENDING",IF(OR(ISNUMBER(SEARCH("Expired",D16)),ISNUMBER(SEARCH("Closed",D16))),"CLOSED/EXPIRED",IF(E16="","NO RELEASE DATE","REVIEW APPROVAL")))) -> CLOSED/EXPIRED | N16: =IF(K16<>"","HIGH: SOURCE CONFLICT",IF(AND(L16="END DATE NOT PASSED",M16="REVIEW APPROVAL"),"HIGH: VERIFY",IF(L16="END DATE NOT PASSED","MEDIUM: CHECK STATUS","LOW: HISTORICAL"))) -> LOW: HISTORICAL | O16: Validar documento firmado, revision/WO/sitio, material afectado y evidencia antes de activar alerta automatica.
A17: CTANJZ04478 | B17: DP524571 | C17: IOTBU | D17: Expired | E17: 45723 | F17: 45775 | G17: 5 | H17: 5 | I17: 73-103150-03 | L17: =IF(F17="","REVIEW: DATE CONFLICT/EMPTY",IF(F17<'Change Overview'!$B$5,"END DATE PASSED","END DATE NOT PASSED")) -> END DATE PASSED | M17: =IF(K17<>"","REVIEW SOURCE CONFLICT",IF(OR(ISNUMBER(SEARCH("CCB",D17)),ISNUMBER(SEARCH("Pending",D17))),"CCB/PENDING",IF(OR(ISNUMBER(SEARCH("Expired",D17)),ISNUMBER(SEARCH("Closed",D17))),"CLOSED/EXPIRED",IF(E17="","NO RELEASE DATE","REVIEW APPROVAL")))) -> CLOSED/EXPIRED | N17: =IF(K17<>"","HIGH: SOURCE CONFLICT",IF(AND(L17="END DATE NOT PASSED",M17="REVIEW APPROVAL"),"HIGH: VERIFY",IF(L17="END DATE NOT PASSED","MEDIUM: CHECK STATUS","LOW: HISTORICAL"))) -> LOW: HISTORICAL | O17: Validar documento firmado, revision/WO/sitio, material afectado y evidencia antes de activar alerta automatica.
A18: CTANJZ04481 | B18: D600361 | C18: STBU | D18: Expired | E18: 45736 | F18: 45809 | G18: 3 | H18: 3 | I18: 73-19332-01 | L18: =IF(F18="","REVIEW: DATE CONFLICT/EMPTY",IF(F18<'Change Overview'!$B$5,"END DATE PASSED","END DATE NOT PASSED")) -> END DATE PASSED | M18: =IF(K18<>"","REVIEW SOURCE CONFLICT",IF(OR(ISNUMBER(SEARCH("CCB",D18)),ISNUMBER(SEARCH("Pending",D18))),"CCB/PENDING",IF(OR(ISNUMBER(SEARCH("Expired",D18)),ISNUMBER(SEARCH("Closed",D18))),"CLOSED/EXPIRED",IF(E18="","NO RELEASE DATE","REVIEW APPROVAL")))) -> CLOSED/EXPIRED | N18: =IF(K18<>"","HIGH: SOURCE CONFLICT",IF(AND(L18="END DATE NOT PASSED",M18="REVIEW APPROVAL"),"HIGH: VERIFY",IF(L18="END DATE NOT PASSED","MEDIUM: CHECK STATUS","LOW: HISTORICAL"))) -> LOW: HISTORICAL | O18: Validar documento firmado, revision/WO/sitio, material afectado y evidencia antes de activar alerta automatica.
A19: CTANJZ04487 | B19: D602439 | C19: SRGBU | D19: Expired | E19: 45732 | F19: 45810 | G19: 1 | H19: 1 | L19: =IF(F19="","REVIEW: DATE CONFLICT/EMPTY",IF(F19<'Change Overview'!$B$5,"END DATE PASSED","END DATE NOT PASSED")) -> END DATE PASSED | M19: =IF(K19<>"","REVIEW SOURCE CONFLICT",IF(OR(ISNUMBER(SEARCH("CCB",D19)),ISNUMBER(SEARCH("Pending",D19))),"CCB/PENDING",IF(OR(ISNUMBER(SEARCH("Expired",D19)),ISNUMBER(SEARCH("Closed",D19))),"CLOSED/EXPIRED",IF(E19="","NO RELEASE DATE","REVIEW APPROVAL")))) -> CLOSED/EXPIRED | N19: =IF(K19<>"","HIGH: SOURCE CONFLICT",IF(AND(L19="END DATE NOT PASSED",M19="REVIEW APPROVAL"),"HIGH: VERIFY",IF(L19="END DATE NOT PASSED","MEDIUM: CHECK STATUS","LOW: HISTORICAL"))) -> LOW: HISTORICAL | O19: Validar documento firmado, revision/WO/sitio, material afectado y evidencia antes de activar alerta automatica.
A20: CTANJZ04493 | B20: D602616 | C20: STBU | D20: Expired | E20: 45742 | F20: 45817 | G20: 6 | H20: 6 | L20: =IF(F20="","REVIEW: DATE CONFLICT/EMPTY",IF(F20<'Change Overview'!$B$5,"END DATE PASSED","END DATE NOT PASSED")) -> END DATE PASSED | M20: =IF(K20<>"","REVIEW SOURCE CONFLICT",IF(OR(ISNUMBER(SEARCH("CCB",D20)),ISNUMBER(SEARCH("Pending",D20))),"CCB/PENDING",IF(OR(ISNUMBER(SEARCH("Expired",D20)),ISNUMBER(SEARCH("Closed",D20))),"CLOSED/EXPIRED",IF(E20="","NO RELEASE DATE","REVIEW APPROVAL")))) -> CLOSED/EXPIRED | N20: =IF(K20<>"","HIGH: SOURCE CONFLICT",IF(AND(L20="END DATE NOT PASSED",M20="REVIEW APPROVAL"),"HIGH: VERIFY",IF(L20="END DATE NOT PASSED","MEDIUM: CHECK STATUS","LOW: HISTORICAL"))) -> LOW: HISTORICAL | O20: Validar documento firmado, revision/WO/sitio, material afectado y evidencia antes de activar alerta automatica.
A21: CTANJZ04503 | B21: D602312 | C21: STBU | D21: Expired | E21: 45748 | F21: 45824 | G21: 3 | H21: 3 | I21: 73-18489-07 | L21: =IF(F21="","REVIEW: DATE CONFLICT/EMPTY",IF(F21<'Change Overview'!$B$5,"END DATE PASSED","END DATE NOT PASSED")) -> END DATE PASSED | M21: =IF(K21<>"","REVIEW SOURCE CONFLICT",IF(OR(ISNUMBER(SEARCH("CCB",D21)),ISNUMBER(SEARCH("Pending",D21))),"CCB/PENDING",IF(OR(ISNUMBER(SEARCH("Expired",D21)),ISNUMBER(SEARCH("Closed",D21))),"CLOSED/EXPIRED",IF(E21="","NO RELEASE DATE","REVIEW APPROVAL")))) -> CLOSED/EXPIRED | N21: =IF(K21<>"","HIGH: SOURCE CONFLICT",IF(AND(L21="END DATE NOT PASSED",M21="REVIEW APPROVAL"),"HIGH: VERIFY",IF(L21="END DATE NOT PASSED","MEDIUM: CHECK STATUS","LOW: HISTORICAL"))) -> LOW: HISTORICAL | O21: Validar documento firmado, revision/WO/sitio, material afectado y evidencia antes de activar alerta automatica.
A22: CTANJZ04504 | B22: D602218 | C22: STBU | D22: Expired | E22: 45748 | F22: 45824 | G22: 3 | H22: 3 | I22: 73-18489-07 | L22: =IF(F22="","REVIEW: DATE CONFLICT/EMPTY",IF(F22<'Change Overview'!$B$5,"END DATE PASSED","END DATE NOT PASSED")) -> END DATE PASSED | M22: =IF(K22<>"","REVIEW SOURCE CONFLICT",IF(OR(ISNUMBER(SEARCH("CCB",D22)),ISNUMBER(SEARCH("Pending",D22))),"CCB/PENDING",IF(OR(ISNUMBER(SEARCH("Expired",D22)),ISNUMBER(SEARCH("Closed",D22))),"CLOSED/EXPIRED",IF(E22="","NO RELEASE DATE","REVIEW APPROVAL")))) -> CLOSED/EXPIRED | N22: =IF(K22<>"","HIGH: SOURCE CONFLICT",IF(AND(L22="END DATE NOT PASSED",M22="REVIEW APPROVAL"),"HIGH: VERIFY",IF(L22="END DATE NOT PASSED","MEDIUM: CHECK STATUS","LOW: HISTORICAL"))) -> LOW: HISTORICAL | O22: Validar documento firmado, revision/WO/sitio, material afectado y evidencia antes de activar alerta automatica.
A23: CTANJZ04506 | B23: D602909 | C23: SRGBU | D23: Expired | E23: 45748 | F23: 45826 | G23: 2 | H23: 2 | L23: =IF(F23="","REVIEW: DATE CONFLICT/EMPTY",IF(F23<'Change Overview'!$B$5,"END DATE PASSED","END DATE NOT PASSED")) -> END DATE PASSED | M23: =IF(K23<>"","REVIEW SOURCE CONFLICT",IF(OR(ISNUMBER(SEARCH("CCB",D23)),ISNUMBER(SEARCH("Pending",D23))),"CCB/PENDING",IF(OR(ISNUMBER(SEARCH("Expired",D23)),ISNUMBER(SEARCH("Closed",D23))),"CLOSED/EXPIRED",IF(E23="","NO RELEASE DATE","REVIEW APPROVAL")))) -> CLOSED/EXPIRED | N23: =IF(K23<>"","HIGH: SOURCE CONFLICT",IF(AND(L23="END DATE NOT PASSED",M23="REVIEW APPROVAL"),"HIGH: VERIFY",IF(L23="END DATE NOT PASSED","MEDIUM: CHECK STATUS","LOW: HISTORICAL"))) -> LOW: HISTORICAL | O23: Validar documento firmado, revision/WO/sitio, material afectado y evidencia antes de activar alerta automatica.
A24: CTANJZ04510 | B24: D601185 | C24: STBU | D24: Expired | E24: 45757 | F24: 45827 | G24: 3 | H24: 3 | I24: 73-20247-05 | L24: =IF(F24="","REVIEW: DATE CONFLICT/EMPTY",IF(F24<'Change Overview'!$B$5,"END DATE PASSED","END DATE NOT PASSED")) -> END DATE PASSED | M24: =IF(K24<>"","REVIEW SOURCE CONFLICT",IF(OR(ISNUMBER(SEARCH("CCB",D24)),ISNUMBER(SEARCH("Pending",D24))),"CCB/PENDING",IF(OR(ISNUMBER(SEARCH("Expired",D24)),ISNUMBER(SEARCH("Closed",D24))),"CLOSED/EXPIRED",IF(E24="","NO RELEASE DATE","REVIEW APPROVAL")))) -> CLOSED/EXPIRED | N24: =IF(K24<>"","HIGH: SOURCE CONFLICT",IF(AND(L24="END DATE NOT PASSED",M24="REVIEW APPROVAL"),"HIGH: VERIFY",IF(L24="END DATE NOT PASSED","MEDIUM: CHECK STATUS","LOW: HISTORICAL"))) -> LOW: HISTORICAL | O24: Validar documento firmado, revision/WO/sitio, material afectado y evidencia antes de activar alerta automatica.
A25: CTANJZ04512 | B25: D602969 | C25: STBU | D25: Expired | E25: 45750 | F25: 45920 | G25: 8 | H25: 8 | I25: 73-20247-05, 73-20249-05 | L25: =IF(F25="","REVIEW: DATE CONFLICT/EMPTY",IF(F25<'Change Overview'!$B$5,"END DATE PASSED","END DATE NOT PASSED")) -> END DATE PASSED | M25: =IF(K25<>"","REVIEW SOURCE CONFLICT",IF(OR(ISNUMBER(SEARCH("CCB",D25)),ISNUMBER(SEARCH("Pending",D25))),"CCB/PENDING",IF(OR(ISNUMBER(SEARCH("Expired",D25)),ISNUMBER(SEARCH("Closed",D25))),"CLOSED/EXPIRED",IF(E25="","NO RELEASE DATE","REVIEW APPROVAL")))) -> CLOSED/EXPIRED | N25: =IF(K25<>"","HIGH: SOURCE CONFLICT",IF(AND(L25="END DATE NOT PASSED",M25="REVIEW APPROVAL"),"HIGH: VERIFY",IF(L25="END DATE NOT PASSED","MEDIUM: CHECK STATUS","LOW: HISTORICAL"))) -> LOW: HISTORICAL | O25: Validar documento firmado, revision/WO/sitio, material afectado y evidencia antes de activar alerta automatica.
A26: CTANJZ04515 | B26: D602888 | C26: STBU | D26: Expired | E26: 45750 | F26: 45830 | G26: 1 | H26: 1 | L26: =IF(F26="","REVIEW: DATE CONFLICT/EMPTY",IF(F26<'Change Overview'!$B$5,"END DATE PASSED","END DATE NOT PASSED")) -> END DATE PASSED | M26: =IF(K26<>"","REVIEW SOURCE CONFLICT",IF(OR(ISNUMBER(SEARCH("CCB",D26)),ISNUMBER(SEARCH("Pending",D26))),"CCB/PENDING",IF(OR(ISNUMBER(SEARCH("Expired",D26)),ISNUMBER(SEARCH("Closed",D26))),"CLOSED/EXPIRED",IF(E26="","NO RELEASE DATE","REVIEW APPROVAL")))) -> CLOSED/EXPIRED | N26: =IF(K26<>"","HIGH: SOURCE CONFLICT",IF(AND(L26="END DATE NOT PASSED",M26="REVIEW APPROVAL"),"HIGH: VERIFY",IF(L26="END DATE NOT PASSED","MEDIUM: CHECK STATUS","LOW: HISTORICAL"))) -> LOW: HISTORICAL | O26: Validar documento firmado, revision/WO/sitio, material afectado y evidencia antes de activar alerta automatica.
A27: CTANJZ04518 | B27: D602944 | C27: CVEBU | D27: Expired | E27: 45751 | F27: 45831 | G27: 1 | H27: 1 | L27: =IF(F27="","REVIEW: DATE CONFLICT/EMPTY",IF(F27<'Change Overview'!$B$5,"END DATE PASSED","END DATE NOT PASSED")) -> END DATE PASSED | M27: =IF(K27<>"","REVIEW SOURCE CONFLICT",IF(OR(ISNUMBER(SEARCH("CCB",D27)),ISNUMBER(SEARCH("Pending",D27))),"CCB/PENDING",IF(OR(ISNUMBER(SEARCH("Expired",D27)),ISNUMBER(SEARCH("Closed",D27))),"CLOSED/EXPIRED",IF(E27="","NO RELEASE DATE","REVIEW APPROVAL")))) -> CLOSED/EXPIRED | N27: =IF(K27<>"","HIGH: SOURCE CONFLICT",IF(AND(L27="END DATE NOT PASSED",M27="REVIEW APPROVAL"),"HIGH: VERIFY",IF(L27="END DATE NOT PASSED","MEDIUM: CHECK STATUS","LOW: HISTORICAL"))) -> LOW: HISTORICAL | O27: Validar documento firmado, revision/WO/sitio, material afectado y evidencia antes de activar alerta automatica.
A28: CTANJZ04523 | B28: DP524680 | C28: IOTBU | D28: Expired | E28: 45751 | F28: 45801 | G28: 2 | H28: 2 | I28: 73-103098-03 | L28: =IF(F28="","REVIEW: DATE CONFLICT/EMPTY",IF(F28<'Change Overview'!$B$5,"END DATE PASSED","END DATE NOT PASSED")) -> END DATE PASSED | M28: =IF(K28<>"","REVIEW SOURCE CONFLICT",IF(OR(ISNUMBER(SEARCH("CCB",D28)),ISNUMBER(SEARCH("Pending",D28))),"CCB/PENDING",IF(OR(ISNUMBER(SEARCH("Expired",D28)),ISNUMBER(SEARCH("Closed",D28))),"CLOSED/EXPIRED",IF(E28="","NO RELEASE DATE","REVIEW APPROVAL")))) -> CLOSED/EXPIRED | N28: =IF(K28<>"","HIGH: SOURCE CONFLICT",IF(AND(L28="END DATE NOT PASSED",M28="REVIEW APPROVAL"),"HIGH: VERIFY",IF(L28="END DATE NOT PASSED","MEDIUM: CHECK STATUS","LOW: HISTORICAL"))) -> LOW: HISTORICAL | O28: Validar documento firmado, revision/WO/sitio, material afectado y evidencia antes de activar alerta automatica.
A29: CTANJZ04524 | B29: D603036 | C29: STBU | D29: Expired | E29: 45751 | F29: 45831 | G29: 2 | H29: 2 | L29: =IF(F29="","REVIEW: DATE CONFLICT/EMPTY",IF(F29<'Change Overview'!$B$5,"END DATE PASSED","END DATE NOT PASSED")) -> END DATE PASSED | M29: =IF(K29<>"","REVIEW SOURCE CONFLICT",IF(OR(ISNUMBER(SEARCH("CCB",D29)),ISNUMBER(SEARCH("Pending",D29))),"CCB/PENDING",IF(OR(ISNUMBER(SEARCH("Expired",D29)),ISNUMBER(SEARCH("Closed",D29))),"CLOSED/EXPIRED",IF(E29="","NO RELEASE DATE","REVIEW APPROVAL")))) -> CLOSED/EXPIRED | N29: =IF(K29<>"","HIGH: SOURCE CONFLICT",IF(AND(L29="END DATE NOT PASSED",M29="REVIEW APPROVAL"),"HIGH: VERIFY",IF(L29="END DATE NOT PASSED","MEDIUM: CHECK STATUS","LOW: HISTORICAL"))) -> LOW: HISTORICAL | O29: Validar documento firmado, revision/WO/sitio, material afectado y evidencia antes de activar alerta automatica.
A30: CTANJZ04526 | B30: D603054 | C30: STBU | D30: Expired | E30: 45752 | F30: 45832 | G30: 4 | H30: 4 | L30: =IF(F30="","REVIEW: DATE CONFLICT/EMPTY",IF(F30<'Change Overview'!$B$5,"END DATE PASSED","END DATE NOT PASSED")) -> END DATE PASSED | M30: =IF(K30<>"","REVIEW SOURCE CONFLICT",IF(OR(ISNUMBER(SEARCH("CCB",D30)),ISNUMBER(SEARCH("Pending",D30))),"CCB/PENDING",IF(OR(ISNUMBER(SEARCH("Expired",D30)),ISNUMBER(SEARCH("Closed",D30))),"CLOSED/EXPIRED",IF(E30="","NO RELEASE DATE","REVIEW APPROVAL")))) -> CLOSED/EXPIRED | N30: =IF(K30<>"","HIGH: SOURCE CONFLICT",IF(AND(L30="END DATE NOT PASSED",M30="REVIEW APPROVAL"),"HIGH: VERIFY",IF(L30="END DATE NOT PASSED","MEDIUM: CHECK STATUS","LOW: HISTORICAL"))) -> LOW: HISTORICAL | O30: Validar documento firmado, revision/WO/sitio, material afectado y evidencia antes de activar alerta automatica.
A31: CTANJZ04532 | B31: DP524725 | C31: STBU | D31: Expired | E31: 45752 | F31: 45804 | G31: 1 | H31: 1 | I31: 73-103558-03 | L31: =IF(F31="","REVIEW: DATE CONFLICT/EMPTY",IF(F31<'Change Overview'!$B$5,"END DATE PASSED","END DATE NOT PASSED")) -> END DATE PASSED | M31: =IF(K31<>"","REVIEW SOURCE CONFLICT",IF(OR(ISNUMBER(SEARCH("CCB",D31)),ISNUMBER(SEARCH("Pending",D31))),"CCB/PENDING",IF(OR(ISNUMBER(SEARCH("Expired",D31)),ISNUMBER(SEARCH("Closed",D31))),"CLOSED/EXPIRED",IF(E31="","NO RELEASE DATE","REVIEW APPROVAL")))) -> CLOSED/EXPIRED | N31: =IF(K31<>"","HIGH: SOURCE CONFLICT",IF(AND(L31="END DATE NOT PASSED",M31="REVIEW APPROVAL"),"HIGH: VERIFY",IF(L31="END DATE NOT PASSED","MEDIUM: CHECK STATUS","LOW: HISTORICAL"))) -> LOW: HISTORICAL | O31: Validar documento firmado, revision/WO/sitio, material afectado y evidencia antes de activar alerta automatica.
A32: CTANJZ04537 | B32: D602319 | C32: STBU | D32: Expired | E32: 45762 | F32: 45837 | G32: 12 | H32: 12 | I32: 73-20247-05, 73-20249-05 | L32: =IF(F32="","REVIEW: DATE CONFLICT/EMPTY",IF(F32<'Change Overview'!$B$5,"END DATE PASSED","END DATE NOT PASSED")) -> END DATE PASSED | M32: =IF(K32<>"","REVIEW SOURCE CONFLICT",IF(OR(ISNUMBER(SEARCH("CCB",D32)),ISNUMBER(SEARCH("Pending",D32))),"CCB/PENDING",IF(OR(ISNUMBER(SEARCH("Expired",D32)),ISNUMBER(SEARCH("Closed",D32))),"CLOSED/EXPIRED",IF(E32="","NO RELEASE DATE","REVIEW APPROVAL")))) -> CLOSED/EXPIRED | N32: =IF(K32<>"","HIGH: SOURCE CONFLICT",IF(AND(L32="END DATE NOT PASSED",M32="REVIEW APPROVAL"),"HIGH: VERIFY",IF(L32="END DATE NOT PASSED","MEDIUM: CHECK STATUS","LOW: HISTORICAL"))) -> LOW: HISTORICAL | O32: Validar documento firmado, revision/WO/sitio, material afectado y evidencia antes de activar alerta automatica.
A33: CTANJZ04545 | B33: D601188 | C33: STBU | D33: Expired | E33: 45769 | F33: 45840 | G33: 3 | H33: 3 | I33: 73-17498-04 | L33: =IF(F33="","REVIEW: DATE CONFLICT/EMPTY",IF(F33<'Change Overview'!$B$5,"END DATE PASSED","END DATE NOT PASSED")) -> END DATE PASSED | M33: =IF(K33<>"","REVIEW SOURCE CONFLICT",IF(OR(ISNUMBER(SEARCH("CCB",D33)),ISNUMBER(SEARCH("Pending",D33))),"CCB/PENDING",IF(OR(ISNUMBER(SEARCH("Expired",D33)),ISNUMBER(SEARCH("Closed",D33))),"CLOSED/EXPIRED",IF(E33="","NO RELEASE DATE","REVIEW APPROVAL")))) -> CLOSED/EXPIRED | N33: =IF(K33<>"","HIGH: SOURCE CONFLICT",IF(AND(L33="END DATE NOT PASSED",M33="REVIEW APPROVAL"),"HIGH: VERIFY",IF(L33="END DATE NOT PASSED","MEDIUM: CHECK STATUS","LOW: HISTORICAL"))) -> LOW: HISTORICAL | O33: Validar documento firmado, revision/WO/sitio, material afectado y evidencia antes de activar alerta automatica.
A34: CTANJZ04552 | B34: D603244 | C34: STBU | D34: Expired | E34: 45771 | F34: 45845 | G34: 9 | H34: 9 | I34: 73-17567-12, 73-17568-12, 73-17569-10, 73-17570-10 | L34: =IF(F34="","REVIEW: DATE CONFLICT/EMPTY",IF(F34<'Change Overview'!$B$5,"END DATE PASSED","END DATE NOT PASSED")) -> END DATE PASSED | M34: =IF(K34<>"","REVIEW SOURCE CONFLICT",IF(OR(ISNUMBER(SEARCH("CCB",D34)),ISNUMBER(SEARCH("Pending",D34))),"CCB/PENDING",IF(OR(ISNUMBER(SEARCH("Expired",D34)),ISNUMBER(SEARCH("Closed",D34))),"CLOSED/EXPIRED",IF(E34="","NO RELEASE DATE","REVIEW APPROVAL")))) -> CLOSED/EXPIRED | N34: =IF(K34<>"","HIGH: SOURCE CONFLICT",IF(AND(L34="END DATE NOT PASSED",M34="REVIEW APPROVAL"),"HIGH: VERIFY",IF(L34="END DATE NOT PASSED","MEDIUM: CHECK STATUS","LOW: HISTORICAL"))) -> LOW: HISTORICAL | O34: Validar documento firmado, revision/WO/sitio, material afectado y evidencia antes de activar alerta automatica.
A35: CTANJZ04555 | B35: D603224 | C35: SRGBU | D35: Expired | E35: 45772 | F35: 45845 | G35: 4 | H35: 4 | L35: =IF(F35="","REVIEW: DATE CONFLICT/EMPTY",IF(F35<'Change Overview'!$B$5,"END DATE PASSED","END DATE NOT PASSED")) -> END DATE PASSED | M35: =IF(K35<>"","REVIEW SOURCE CONFLICT",IF(OR(ISNUMBER(SEARCH("CCB",D35)),ISNUMBER(SEARCH("Pending",D35))),"CCB/PENDING",IF(OR(ISNUMBER(SEARCH("Expired",D35)),ISNUMBER(SEARCH("Closed",D35))),"CLOSED/EXPIRED",IF(E35="","NO RELEASE DATE","REVIEW APPROVAL")))) -> CLOSED/EXPIRED | N35: =IF(K35<>"","HIGH: SOURCE CONFLICT",IF(AND(L35="END DATE NOT PASSED",M35="REVIEW APPROVAL"),"HIGH: VERIFY",IF(L35="END DATE NOT PASSED","MEDIUM: CHECK STATUS","LOW: HISTORICAL"))) -> LOW: HISTORICAL | O35: Validar documento firmado, revision/WO/sitio, material afectado y evidencia antes de activar alerta automatica.
A36: CTANJZ04556 | B36: D603102 | C36: STBU | D36: Expired | E36: 45771 | F36: 45936 | G36: 6 | H36: 6 | I36: 73-20247-05, 73-20249-05 | L36: =IF(F36="","REVIEW: DATE CONFLICT/EMPTY",IF(F36<'Change Overview'!$B$5,"END DATE PASSED","END DATE NOT PASSED")) -> END DATE PASSED | M36: =IF(K36<>"","REVIEW SOURCE CONFLICT",IF(OR(ISNUMBER(SEARCH("CCB",D36)),ISNUMBER(SEARCH("Pending",D36))),"CCB/PENDING",IF(OR(ISNUMBER(SEARCH("Expired",D36)),ISNUMBER(SEARCH("Closed",D36))),"CLOSED/EXPIRED",IF(E36="","NO RELEASE DATE","REVIEW APPROVAL")))) -> CLOSED/EXPIRED | N36: =IF(K36<>"","HIGH: SOURCE CONFLICT",IF(AND(L36="END DATE NOT PASSED",M36="REVIEW APPROVAL"),"HIGH: VERIFY",IF(L36="END DATE NOT PASSED","MEDIUM: CHECK STATUS","LOW: HISTORICAL"))) -> LOW: HISTORICAL | O36: Validar documento firmado, revision/WO/sitio, material afectado y evidencia antes de activar alerta automatica.
A37: CTANJZ04557 | B37: D603243 | C37: STBU | D37: Expired | E37: 45771 | F37: 45847 | G37: 9 | H37: 9 | I37: 73-18488-07, 73-18489-07, 73-18490-09, 73-21007-02 | L37: =IF(F37="","REVIEW: DATE CONFLICT/EMPTY",IF(F37<'Change Overview'!$B$5,"END DATE PASSED","END DATE NOT PASSED")) -> END DATE PASSED | M37: =IF(K37<>"","REVIEW SOURCE CONFLICT",IF(OR(ISNUMBER(SEARCH("CCB",D37)),ISNUMBER(SEARCH("Pending",D37))),"CCB/PENDING",IF(OR(ISNUMBER(SEARCH("Expired",D37)),ISNUMBER(SEARCH("Closed",D37))),"CLOSED/EXPIRED",IF(E37="","NO RELEASE DATE","REVIEW APPROVAL")))) -> CLOSED/EXPIRED | N37: =IF(K37<>"","HIGH: SOURCE CONFLICT",IF(AND(L37="END DATE NOT PASSED",M37="REVIEW APPROVAL"),"HIGH: VERIFY",IF(L37="END DATE NOT PASSED","MEDIUM: CHECK STATUS","LOW: HISTORICAL"))) -> LOW: HISTORICAL | O37: Validar documento firmado, revision/WO/sitio, material afectado y evidencia antes de activar alerta automatica.
A38: CTANJZ04568 | B38: D603037 | C38: STBU | D38: Expired | E38: 45779 | F38: 45853 | G38: 23 | H38: 23 | L38: =IF(F38="","REVIEW: DATE CONFLICT/EMPTY",IF(F38<'Change Overview'!$B$5,"END DATE PASSED","END DATE NOT PASSED")) -> END DATE PASSED | M38: =IF(K38<>"","REVIEW SOURCE CONFLICT",IF(OR(ISNUMBER(SEARCH("CCB",D38)),ISNUMBER(SEARCH("Pending",D38))),"CCB/PENDING",IF(OR(ISNUMBER(SEARCH("Expired",D38)),ISNUMBER(SEARCH("Closed",D38))),"CLOSED/EXPIRED",IF(E38="","NO RELEASE DATE","REVIEW APPROVAL")))) -> CLOSED/EXPIRED | N38: =IF(K38<>"","HIGH: SOURCE CONFLICT",IF(AND(L38="END DATE NOT PASSED",M38="REVIEW APPROVAL"),"HIGH: VERIFY",IF(L38="END DATE NOT PASSED","MEDIUM: CHECK STATUS","LOW: HISTORICAL"))) -> LOW: HISTORICAL | O38: Validar documento firmado, revision/WO/sitio, material afectado y evidencia antes de activar alerta automatica.
A39: CTANJZ04571 | B39: D603340 | C39: IOTBU | D39: Expired | E39: 45773 | F39: 45855 | G39: 1 | H39: 1 | L39: =IF(F39="","REVIEW: DATE CONFLICT/EMPTY",IF(F39<'Change Overview'!$B$5,"END DATE PASSED","END DATE NOT PASSED")) -> END DATE PASSED | M39: =IF(K39<>"","REVIEW SOURCE CONFLICT",IF(OR(ISNUMBER(SEARCH("CCB",D39)),ISNUMBER(SEARCH("Pending",D39))),"CCB/PENDING",IF(OR(ISNUMBER(SEARCH("Expired",D39)),ISNUMBER(SEARCH("Closed",D39))),"CLOSED/EXPIRED",IF(E39="","NO RELEASE DATE","REVIEW APPROVAL")))) -> CLOSED/EXPIRED | N39: =IF(K39<>"","HIGH: SOURCE CONFLICT",IF(AND(L39="END DATE NOT PASSED",M39="REVIEW APPROVAL"),"HIGH: VERIFY",IF(L39="END DATE NOT PASSED","MEDIUM: CHECK STATUS","LOW: HISTORICAL"))) -> LOW: HISTORICAL | O39: Validar documento firmado, revision/WO/sitio, material afectado y evidencia antes de activar alerta automatica.
A40: CTANJZ04573 | B40: D603428 | C40: SRGBU | D40: Expired | E40: 45779 | F40: 45858 | G40: 1 | H40: 1 | L40: =IF(F40="","REVIEW: DATE CONFLICT/EMPTY",IF(F40<'Change Overview'!$B$5,"END DATE PASSED","END DATE NOT PASSED")) -> END DATE PASSED | M40: =IF(K40<>"","REVIEW SOURCE CONFLICT",IF(OR(ISNUMBER(SEARCH("CCB",D40)),ISNUMBER(SEARCH("Pending",D40))),"CCB/PENDING",IF(OR(ISNUMBER(SEARCH("Expired",D40)),ISNUMBER(SEARCH("Closed",D40))),"CLOSED/EXPIRED",IF(E40="","NO RELEASE DATE","REVIEW APPROVAL")))) -> CLOSED/EXPIRED | N40: =IF(K40<>"","HIGH: SOURCE CONFLICT",IF(AND(L40="END DATE NOT PASSED",M40="REVIEW APPROVAL"),"HIGH: VERIFY",IF(L40="END DATE NOT PASSED","MEDIUM: CHECK STATUS","LOW: HISTORICAL"))) -> LOW: HISTORICAL | O40: Validar documento firmado, revision/WO/sitio, material afectado y evidencia antes de activar alerta automatica.
...

Sheet Deviation Instructions
A1: CTAN Number | B1: Customer Deviation# | C1: SKU (document text) | D1: Target PN | E1: RefDes | F1: Change Operation | G1: Old / Remove CPN | H1: New / Add CPN | I1: Proposed Validation | J1: Source Excerpt (verbatim) | K1: Source Workflow | L1: Effective Until (source) | M1: Auto Gate | N1: Review State | O1: Source File | P1: Critical Note
A2: CTANJZ05414 | B2: D613039 | C2: HEIMDALL | D2: 73-103459-02 | E2: U65 | F2: REMOVE | G2: 15-109506-01 | I2: BOM / P&P / FAI | J2: Remove U65/15-109506-01 from BOM | K2: FAI Status | L2: 2026-10-29 | M2: NO - PENDING REVIEW | N2: Pending Review | O2: Deviation.csv | P2: Aplica solo si la desviacion se usa en la WO; requiere confirmar sustitucion Renesas/TI. El PN 73-103758-04 se menciona como referencia, no como BOM objetivo.
A3: CTANJZ05414 | B3: D613039 | C3: HEIMDALL | D3: 73-103459-02 | E3: U66 | F3: ADD | H3: 15-109628-01 | I3: BOM / P&P / FAI | J3: Add U66/15-109628-01 to BOM | K3: FAI Status | L3: 2026-10-29 | M3: NO - PENDING REVIEW | N3: Pending Review | O3: Deviation.csv | P3: Aplica solo si la desviacion se usa en la WO; requiere confirmar sustitucion Renesas/TI. El PN 73-103758-04 se menciona como referencia, no como BOM objetivo.
A4: CTANJZ05414 | B4: D613039 | C4: HEIMDALL | D4: 73-103459-02 | E4: R149 | F4: REPLACE | G4: 12-4443-01 | H4: 12-2567-02 | I4: BOM / P&P / ICT | J4: Change R149 from 12-4443-01 to 12-2567-02 | K4: FAI Status | L4: 2026-10-29 | M4: NO - PENDING REVIEW | N4: Pending Review | O4: Deviation.csv | P4: Aplica solo si la desviacion se usa en la WO; requiere confirmar sustitucion Renesas/TI. El PN 73-103758-04 se menciona como referencia, no como BOM objetivo.
A5: CTANJZ05414 | B5: D613039 | C5: HEIMDALL | D5: 73-103459-02 | E5: R151 | F5: REPLACE | G5: 12-100278-01 | H5: 12-4978-01 | I5: BOM / P&P / ICT | J5: Change R151 from 12-100278-01 to 12-4978-01 | K5: FAI Status | L5: 2026-10-29 | M5: NO - PENDING REVIEW | N5: Pending Review | O5: Deviation.csv | P5: Aplica solo si la desviacion se usa en la WO; requiere confirmar sustitucion Renesas/TI. El PN 73-103758-04 se menciona como referencia, no como BOM objetivo.
A6: CTANJZ05519 | B6: D614380 | C6: PICTORIS | D6: 73-103603-05 | E6: U417 | F6: REPLACE | G6: 15-108939-01 | H6: 15-108939-03 | I6: BOM / AOI / FAI | J6: For refdes U417Remove from BOM15-108939-01 | K6: CCB | L6: 2027-01-01 | M6: NO - PENDING REVIEW | N6: Pending Review | O6: Deviation.csv | P6: CSV en estado CCB; NO aprobado. La revision B0 consta en descripcion, confirmar aplicabilidad para cada PCBA.
A7: CTANJZ05519 | B7: D614380 | C7: PICTORIS | D7: 73-103103-05 | E7: U417 | F7: REPLACE | G7: 15-108939-01 | H7: 15-108939-03 | I7: BOM / AOI / FAI | J7: For refdes U417Remove from BOM15-108939-01 | K7: CCB | L7: 2027-01-01 | M7: NO - PENDING REVIEW | N7: Pending Review | O7: Deviation.csv | P7: CSV en estado CCB; NO aprobado. La revision B0 consta en descripcion, confirmar aplicabilidad para cada PCBA.
A8: CTANJZ05408 | B8: D613038 | C8: TYNE | D8: 68-104853-01 | F8: MODULE_REPLACE | G8: 800-117978-03 | H8: 800-118978-03 | I8: Assembly BOM / module PN / FAI | J8: FJZ is hereby allowed to replace Taylor Module CPN 800-117978-03 with 800-118978-03 | K8: FAI Status | L8: 2026-10-27 | M8: NO - PENDING REVIEW | N8: Pending Review | O8: Deviation.csv | P8: Cambiar MODULO completo; la descripcion indica explicitamente que 15-110522-02 NO reemplaza individualmente 15-110522-01.
A9: CTANJZ05408 | B9: D613038 | C9: TYNE | D9: 68-104854-01 | F9: MODULE_REPLACE | G9: 800-117978-03 | H9: 800-118978-03 | I9: Assembly BOM / module PN / FAI | J9: FJZ is hereby allowed to replace Taylor Module CPN 800-117978-03 with 800-118978-03 | K9: FAI Status | L9: 2026-10-27 | M9: NO - PENDING REVIEW | N9: Pending Review | O9: Deviation.csv | P9: Cambiar MODULO completo; la descripcion indica explicitamente que 15-110522-02 NO reemplaza individualmente 15-110522-01.

Sheet Traducciones ECN ECO
A1: SMTinel Yokoten | Descripciones del customer en español
A2: Objetivo | B2: Mostrar primero el resumen y la traducción técnica en español sin eliminar el original en inglés.
A3: Alcance actual | B3: 487 desviaciones + 728 ECO con numero de documento valido. 464 filas de CSV sin ECO # quedan en ECO Items como no vinculadas; no se inventan documentos ECN.
A4: Cambio solicitado | B4: Para ECO: Related Document=Agile ECN; Match por PCBA PN EXACTO y New Rev EXACTA; Old Rev es la transicion de origen, no una segunda aplicabilidad.
A5: Summary ES | B5: Síntesis de impacto: producto, PN, referencias, sustitución y condición de validación.
A6: Change Description ES | B6: Traducción técnica fiel del texto original; NO alterar códigos, CPN/MPN, PN, RefDes, revision ni unidades.
A7: Translation Review | B7: Traduccion para consulta / Requiere revision: este campo jamás significa que el cambio está aprobado.
A8: Texto original | B8: Se conserva intacto en Change Register / Change Description y se muestra expandible en Yokoten.
A9: Sin traducción | B9: Yokoten debe mostrar "Traducción pendiente" y permitir consultar el texto original. No inventar traducción.
A10: Fuente de verdad | B10: Estado, aplicabilidad y vigencia provienen del documento oficial; la traducción solo ayuda a leerlo.
A11: Priorizacion | B11: Traducir primero los ECO que realmente coinciden por PN y nueva revisión; conservar original del customer sin cambios.
A12: Nota sobre desviaciones | B12: Se prepararon 10 traducciones técnicas de documentos ejemplares; las 477 restantes conservan el texto inglés.
A13: Flujo GitHub | B13: Publicar el libro actualizado como SMTinel_Yokoten_Knowledge_DB.xlsx en el repositorio para lectura dinámica.

Sheet Qualification
A1: Record ID | B1: Product | C1: Part Number | D1: Rev | E1: Side | F1: Line | G1: Status | H1: P&P Program | I1: AOI Library | J1: Last Qualification | K1: Owner | L1: FAI Link | M1: SOP Link | N1: Notes | O1: Active
A2: QUAL-PICTORIS-B0-L13 | B2: PICTORIS | C2: 73-103603-05 | D2: B0 | E2: Top | F2: L13 | G2: Requal Required | N2: Queja histórica por orientación de J73. Actualizar la calificación después de revisar los controles. | O2: Y
A3: QUAL-PICTORIS-B0-L17 | B3: PICTORIS | C3: 73-103603-05 | D3: B0 | E3: Top | F3: L17 | G3: Requal Required | N3: Aplicar esta lección antes de liberar la línea. | O3: Y

Sheet Findings
A1: Finding ID | B1: Scope | C1: Product | D1: Part Number | E1: Component CPN | F1: RefDes | G1: Rev | H1: Line | I1: Finding | J1: Critical Characteristic | K1: Migration Gate | L1: Severity | M1: Source | N1: 8D / LL Link | O1: Status | P1: Owner | Q1: Active
A2: LL-PICTORIS-J73 | B2: PRODUCT | C2: PICTORIS | D2: 73-103603-05 | E2: 27-100137-01 | F2: J73 | G2: B0 | H2: L13 | I2: Queja de cliente: J73 se instaló al revés. | J2: Orientación de J73. El cuerpo blanco va hacia el pin 1. No usar el triángulo como guía. | K2: Antes de liberar la línea, confirmar que el cuerpo blanco apunta al pin 1. Revisar la orientación con AOI y en la primera pieza. | L2: Critical | M2: Queja de cliente / lección 8D | O2: Open | Q2: Y
A3: LL-PICTORIS-J73-L13 | B3: PRODUCT_REV_LINE | C3: PICTORIS | D3: 73-103603-05 | E3: 27-100137-01 | F3: J73 | G3: B0 | H3: L13 | I3: La revisión de AOI no detectó J73 instalado al revés. | J3: Orientación de J73. El cuerpo blanco va hacia el pin 1. No usar el triángulo como guía. | K3: Probar que AOI detecte una pieza correcta y otra con J73 al revés. Repetir la prueba al calificar o recalificar la línea. | L3: High | M3: Hallazgo histórico de línea | O3: Open | Q3: Y
A4: LL-PICTORIS-WO-IDENTITY | B4: PRODUCT | C4: PICTORIS | D4: 73-103603-05 | I4: Se usó una revisión incorrecta y, en otra orden, un número de parte incorrecto. | J4: Número de parte y revisión liberada de la orden de trabajo. | K4: Antes de crear o liberar la orden, confirmar número de parte y revisión. Revisar modelo, número de parte y revisión en la primera pieza. | L4: High | M4: Control de cambios 2026-09-15 · EVT-08 / EVT-09 | O4: Open | P4: Planeación / PM | Q4: Y
A5: LL-BAYFRONT-BOM-LOADLIST | B5: PRODUCT | C5: BAYFRONT | D5: 73-103826-05 | I5: La lista de carga no coincidía con la BOM: había diferencias en parte, posición o cantidad. | J5: Coincidencia entre BOM liberada y lista de carga. | K5: Antes de aprobar la lista de carga, comparar número de parte, posición, cantidad y revisión contra la BOM liberada. | L5: Medium | M5: Control de cambios 2026-09-15 · EVT-01 | O5: Open | P5: Programación / Calidad | Q5: Y
A6: LL-ARATA-ODM-CONFIG | B6: REVISION | C6: ARATA | D6: 74-133408-02 | G6: B0 | I6: El número de parte por sí solo no identifica esta configuración. U58, la revisión y el cambio deben coincidir en SMT e ICT. | J6: Configuración correcta: U58, revisión y cambio liberado. | K6: Antes de liberar, confirmar U58, revisión y cambio en la orden. Revisar que SMT e ICT usen la misma configuración y pruebas. | L6: High | M6: Control de cambios 2026-09-15 · EVT-02 / EVT-03 / EVT-04 | O6: Open | P6: Planeación / Producto / SMT / ICT | Q6: Y
A7: LL-TAYLOR-LARGE-BODY-CLEARANCE | B7: PRODUCT | C7: TAYLOR | I7: Algunos componentes grandes quedan demasiado cerca o se tocan. AOI no siempre detecta esta separación. | J7: Separación entre componentes y tamaño aprobado del cuerpo. | K7: Antes de liberar, revisar tamaño, centrado y posición de los componentes. Medir la separación después de colocar y soldar. Repetir si cambia el proveedor o componente. | L7: High | M7: Control de cambios 2026-09-15 · EVT-19 / EVT-20 / EVT-21; caso Taylor | O7: Open | P7: Carlos Martínez / Josué Rangel / José Cruz | Q7: Y
A8: LL-NIXIE-MIC-SEATING | B8: PRODUCT | C8: NIXIE | I8: El micrófono puede levantarse o mover las bolas de soldadura si se presiona demasiado. Se probaron boquillas y ajustes; la causa aún no está confirmada. | J8: Asiento del micrófono y bolas de soldadura sin desplazamiento. | K8: Usar la boquilla y los ajustes aprobados por el proveedor. Revisar después de colocar y soldar. Revalidar si cambia el proveedor, la boquilla o el programa. | L8: High | M8: Caso SMTinel NIXIE Q1WK08 / WK10 | N8: https://chatgpt.com/c/6ab960a3-208c-83e8-8009-8c18a39dd451 | O8: Monitoring | P8: SMT-P&P / Carlos Martínez | Q8: Y
A9: LL-TUFNELL-DEVIATION-SCOPE-HI | B9: PRODUCT | C9: TUFNELL PARK | D9: 73-20247-06 | E9: 15-102981-01; 15-102981-02 | F9: U23 | I9: Una desviación de CRBU podría permitir material cancelado en NGFWBU, donde no aplica. | J9: La desviación de U23 solo aplica al producto y orden aprobados. | K9: Antes de aceptar el material, confirmar unidad de negocio, producto y orden contra la desviación. Si no coinciden, mantener el bloqueo en SAP. | L9: Critical | M9: Análisis de desviación CRBU / NGFWBU | O9: Open | Q9: Y
A10: LL-TUFNELL-DEVIATION-SCOPE-LO | B10: PRODUCT | C10: TUFNELL PARK | D10: 73-20249-06 | E10: 15-102981-01; 15-102981-02 | F10: U23 | I10: Una desviación de CRBU podría permitir material cancelado en NGFWBU, donde no aplica. | J10: La desviación de U23 solo aplica al producto y orden aprobados. | K10: Antes de aceptar el material, confirmar unidad de negocio, producto y orden contra la desviación. Si no coinciden, mantener el bloqueo en SAP. | L10: Critical | M10: Análisis de desviación CRBU / NGFWBU | O10: Open | Q10: Y
A11: LL-CHARON-CR95-POLARITY | B11: PRODUCT | C11: CHARON | D11: 73-21231-05 | E11: 25-100369-01 | F11: CR95 | G11: C0 | H11: L13 | I11: CR95 se encontró al revés. En esta pieza, la marca verde indica el ánodo. La tablilla tiene el silkscreen al contrario: no guiarse por él. | J11: Orientación de CR95. La marca verde va en sentido opuesto a la marca de polaridad del silkscreen. | K11: Antes de liberar, revisar que la marca verde quede al lado opuesto al silkscreen de polaridad. Usar la ayuda visual aprobada. | L11: Critical | M11: Revisión del caso Charon / correo de polaridad CR95 | O11: Closed | Q11: Y
A12: LL-PICTORIS-BOTON-FLUX | B12: PRODUCT | C12: PICTORIS | D12: 73-103603-05 | E12: 22-100214-01 | F12: S1 | I12: El flux aplicado directamente al cuerpo del botón reprodujo el atasco. El botón puede quedar húmedo o pegajoso y los residuos solidificarse con las horas. Rechazar y reemplazar si hay humedad por flux, pegajosidad o residuos, aunque todavía funcione. | J12: Botón sin flux ni residuos, con accionamiento y retorno libres. | K12: Antes del retrabajo, proteger con Kapton toda el área de conectores y el cuerpo del botón, sin presionar el actuador. No aplicar flux al componente. Revisar al 100 % antes y después. Ante contaminación, reemplazar sin esperar al atasco. Para probar el botón, presionar solo con el dedo. No usar pinzas puntiagudas. | M12: Alerta de calidad CVEBU QAF350 Rev03. Experimento y criterios reportados el 30/09/2026. | O12: Open | Q12: Y
A13: LL-MILLENIUM-BOTON-FLUX | B13: PRODUCT | C13: MILLENIUM | D13: 73-102226-06 | E13: 22-100214-01 | F13: S1 | I13: El flux aplicado directamente al cuerpo del botón reprodujo el atasco. El botón puede quedar húmedo o pegajoso y los residuos solidificarse con las horas. Rechazar y reemplazar si hay humedad por flux, pegajosidad o residuos, aunque todavía funcione. | J13: Botón sin flux ni residuos, con accionamiento y retorno libres. | K13: Antes del retrabajo, proteger con Kapton toda el área de conectores y el cuerpo del botón, sin presionar el actuador. No aplicar flux al componente. Revisar al 100 % antes y después. Ante contaminación, reemplazar sin esperar al atasco. Para probar el botón, presionar solo con el dedo. No usar pinzas puntiagudas. | M13: Alerta de calidad CVEBU QAF350 Rev03. Experimento y criterios reportados el 30/09/2026. | O13: Open | Q13: Y
A14: LL-OCTAVIO-BOTON-FLUX | B14: PRODUCT | C14: OCTAVIO | D14: 73-102701-01 | E14: 22-100214-01 | F14: S1 | I14: El flux aplicado directamente al cuerpo del botón reprodujo el atasco. El botón puede quedar húmedo o pegajoso y los residuos solidificarse con las horas. Rechazar y reemplazar si hay humedad por flux, pegajosidad o residuos, aunque todavía funcione. | J14: Botón sin flux ni residuos, con accionamiento y retorno libres. | K14: Antes del retrabajo, proteger con Kapton toda el área de conectores y el cuerpo del botón, sin presionar el actuador. No aplicar flux al componente. Revisar al 100 % antes y después. Ante contaminación, reemplazar sin esperar al atasco. Para probar el botón, presionar solo con el dedo. No usar pinzas puntiagudas. | M14: Alerta de calidad CVEBU QAF350 Rev03. Experimento y criterios reportados el 30/09/2026. | O14: Open | Q14: Y
A15: LL-BROOKLYN-BOTON-FLUX | B15: PRODUCT | C15: BROOKLYN | D15: 73-102022-02 | E15: 22-100214-01 | F15: S1 | I15: El flux aplicado directamente al cuerpo del botón reprodujo el atasco. El botón puede quedar húmedo o pegajoso y los residuos solidificarse con las horas. Rechazar y reemplazar si hay humedad por flux, pegajosidad o residuos, aunque todavía funcione. | J15: Botón sin flux ni residuos, con accionamiento y retorno libres. | K15: Antes del retrabajo, proteger con Kapton toda el área de conectores y el cuerpo del botón, sin presionar el actuador. No aplicar flux al componente. Revisar al 100 % antes y después. Ante contaminación, reemplazar sin esperar al atasco. Para probar el botón, presionar solo con el dedo. No usar pinzas puntiagudas. | M15: Alerta de calidad CVEBU QAF350 Rev03. Experimento y criterios reportados el 30/09/2026. | O15: Open | Q15: Y
A16: LL-DAVINCI-BOTON-FLUX | B16: PRODUCT | C16: DAVINCI | D16: 73-102797-02 | E16: 22-100214-01 | F16: S1 | I16: El flux aplicado directamente al cuerpo del botón reprodujo el atasco. El botón puede quedar húmedo o pegajoso y los residuos solidificarse con las horas. Rechazar y reemplazar si hay humedad por flux, pegajosidad o residuos, aunque todavía funcione. | J16: Botón sin flux ni residuos, con accionamiento y retorno libres. | K16: Antes del retrabajo, proteger con Kapton toda el área de conectores y el cuerpo del botón, sin presionar el actuador. No aplicar flux al componente. Revisar al 100 % antes y después. Ante contaminación, reemplazar sin esperar al atasco. Para probar el botón, presionar solo con el dedo. No usar pinzas puntiagudas. | M16: Alerta de calidad CVEBU QAF350 Rev03. Experimento y criterios reportados el 30/09/2026. | O16: Open | Q16: Y
A17: LL-HEIMDALL-CLIP-CUSTODY | B17: REVISION | C17: HEIMDALL | D17: 73-103459-02 | E17: 700-136420-01 | F17: J3-J8 | G17: A0 | I17: El cambio agregó clips en J3-J8, pero no quedó claro qué proceso los instala ni cómo se revisan. | J17: Clip presente y fijo en J3-J8. Contacto dorado limpio y proceso de ensamble definido. | K17: Antes de liberar un cambio, definir quién instala cada pieza, cómo se instala y cómo se revisa. Si no está claro, detener la liberación y pedir aclaración al equipo del cliente. | L17: Critical | M17: PCAMAP 61-107350-02 · investigación del clip Heimdall | O17: Open | Q17: Y
A18: LL-GREENFORD-AOI-MARCADO | B18: PRODUCT | C18: GREENFORD | D18: 73-104532-01 | E18: 17-103689-02; 17-103691-01; 17-102460-07 | I18: El usuario reportó un paro de 5 horas en tercer turno después de aceptar material reprogramado y ajustar OCV/OCR en otra corrida. La decisión no quedó disponible para todas las librerías/turnos. El reply aclara C1 como identificación aceptada y solicita referencia oficial. Lección: una liberación local requiere referencia controlada y despliegue verificado por CPN. El historial de cambios debe comprobar la propagación real. | J18: Identificación autorizada del material reprogramado y revisión vigente OCV/OCR | K18: Antes del cambio de modelo o línea, cotejar PN, programación, marcado autorizado y librería vigente. Sin referencia oficial disponible, retener y escalar. No extender C1 a otros PN o programaciones por semejanza. | M18: Chat Análisis de causa raíz, 01/10/2026. Relato del usuario y síntesis de PILOTO GREENFORD / Re: PILOTO GREENFORD. La revisión de los adjuntos debe respaldar la autorización. | N18: https://chatgpt.com/g/g-p-6abe462c09308191916f0eed68e0b198/c/6abe43f8-a784-83e8-9f10-f6d0d31564a3 | O18: Open | Q18: Y
A19: LL-BROOKLYN-S1-ACCIONAMIENTO | B19: PRODUCT | C19: BROOKLYN | D19: 73-102022-02 | E19: 22-100214-01 | F19: S1 | I19: En el experimento con 5 unidades Brooklyn se reportó que el accionamiento con tweezer puntiaguda podía sacar el actuador de sus guías. Lección: la verificación del botón debe detectar la falla sin introducir daño. El ensayo de alcohol/flux corresponde a LL-BROOKLYN-BOTON-FLUX y no prueba inmunidad ante todos los procesos de limpieza. | J19: Accionamiento y retorno de S1 sin fuerza lateral ni herramienta punzante | K19: Definir en WI el método de accionamiento controlado. Antes/después del retrabajo revisar retorno libre, atasco, retorno lento, decoloración y residuos. Separar defecto previo de daño durante inspección. | M19: Chat Investigación profunda 8D, 30/09/2026. Experimento en 5 Brooklyn recuperado del historial: flux reprodujo atasco; alcohol no lo reprodujo en esa muestra; observación de tweezer. | N19: https://chatgpt.com/g/g-p-6ab5f35ed9d08191805565e89e7b1a6d/c/6ab7e69c-30b0-83e8-a989-621112ddf261 | O19: Open | Q19: Y
A20: LL-CVEBU-S1-TERMICO | B20: PRODUCT | C20: CVEBU | E20: 22-100214-01 | F20: S1 | I20: Se observó que el calor de retrabajo se propaga por la PCB hasta el botón. La degradación del mecanismo por conducción a través de cobre es una hipótesis contribuyente pendiente de medición. Lección de investigación: medir temperatura e historial de ciclos antes de atribuir el atasco al layout. La distancia en assembly drawing no demuestra aislamiento térmico. | J20: Exposición térmica indirecta y acumulada de S1 durante retrabajo | K20: Evaluar cada producto/revisión por separado. Medir cuerpo y terminal de S1, zona intervenida y referencia PCB; correlacionar con fuerza, recorrido y retorno. No fijar distancia o límite térmico sin especificación y validación. | M20: Chat Estándares IPC Térmicos, 01/10/2026. Observación del usuario y plan experimental propuesto. Productos a comparar: Pictoris, Millenium, Octavio, Brooklyn y Davinci. | N20: https://chatgpt.com/g/g-p-6ab5f35ed9d08191805565e89e7b1a6d/c/6abf35e3-0b6c-83e8-a8c2-defe530ca3f4 | O20: Open | Q20: N
A21: LL-LANCER-CAP-PREICT | B21: PRODUCT | C21: LANCER | E21: 11-101935-01 | I21: Las validaciones reportadas el 01/10/2026 encontraron el mismo síntoma de capacitor antes de ICT, incluida una unidad que nunca pasó por ICT. Esto descarta ICT como causa iniciadora de toda la población. Lección: localizar primero el punto de introducción y comparar por RefDes/circuito y población de origen. La concentración QSFP o diferencia por date code no confirma causalidad. | J21: Condición del capacitor antes de ICT y localización de la primera degradación | K21: Comparar evidencia pre-ICT/post-ICT y trazabilidad por WO, lote y RefDes. No liberar ni cerrar la investigación suponiendo picos ICT o que todos los componentes de un lote deban fallar. | M21: Chat Traducir reporte a inglés / Lancer, 30/09–01/10/2026. Validaciones posteriores descartan ICT como origen. Síntesis del correo: FJZ303626L6 y FJZ303609VF. PN de board y RefDes exactos pendientes. | N21: https://chatgpt.com/c/6abd16d8-6e58-83e8-90e0-5c916d86d0f1 | O21: Open | Q21: Y
A22: LL-VORETJ-PTH-PUENTES | B22: PRODUCT | C22: VoreTJ-48PXPLX | D22: 73-103083-04 | E22: 29-102727-02 | F22: J2/J4/J7/J13 | I22: En Quake/Mobius se reportaron 27 seriales con puentes físicos en conectores, provenientes de distintas WOs/líneas SMT. La ola PTH fue el proceso común observado, pero no se confirmó causa raíz. Lección: definir la población por genealogía de proceso y verificar físicamente el defecto antes de adjudicarlo a una línea SMT o a proveedor. | J22: Ausencia de puentes de soldadura en conectores después de PTH | K22: Inspeccionar las referencias afectadas después de PTH y segregar desde el último serial conforme ante recurrencia. Revalidar receta y controles cuando cambien ola, pallet, producto o parámetros. | M22: Chat Quake/Mobius, 04/08/2026 hora México / 05/08 UTC. Relato de 27 SN; síntesis del historial: PTH P21S1CT1/P21S4CT1 y RefDes J2/J4/J7/J13. Causa raíz pendiente. | O22: Open | Q22: Y
